Workbook
Name avg_equity: Ratios!$C$33
Name avg_total_assets: Ratios!$C$34
Name avg_total_capitalization: Ratios!$C$35
Name BAL_assets_current_2024: 'Balance Sheet'!$C$9
Name BAL_assets_total_2023: 'Balance Sheet'!$D$20
Name BAL_assets_total_2024: 'Balance Sheet'!$C$20
Name BAL_cash_marketable_securities_2024: 'Balance Sheet'!$C$5
Name BAL_debt_long_term_2023: 'Balance Sheet'!$H$10
Name BAL_debt_long_term_2024: 'Balance Sheet'!$G$10
Name BAL_equity_shareholders_2023: 'Balance Sheet'!$H$18
Name BAL_equity_shareholders_2024: 'Balance Sheet'!$G$18
Name BAL_inventories_2023: 'Balance Sheet'!$D$7
Name BAL_liabilities_current_2024: 'Balance Sheet'!$G$8
Name BAL_liabilities_total_2024: 'Balance Sheet'!$G$13
Name BAL_receivables_2023: 'Balance Sheet'!$D$6
Name BAL_receivables_2024: 'Balance Sheet'!$C$6
Name cost_capital: Ratios!$C$7
Name currentYear_after_tax_operating_income: Ratios!$C$19
Name currentYear_assets_current: Ratios!$C$23
Name currentYear_assets_total: Ratios!$C$28
Name currentYear_cash_marketable_securities: Ratios!$C$22
Name currentYear_cost_goods_sold_daily: Ratios!$C$25
Name currentYear_daily_sales_average: Ratios!$C$20
Name currentYear_debt_long_term: Ratios!$C$26
Name currentYear_equity: Ratios!$C$21
Name currentYear_liabilities_current: Ratios!$C$24
Name currentYear_liabilities_total: Ratios!$C$30
Name currentYear_total_capitalization: Ratios!$C$29
Name currentYear_woking_capital_net: Ratios!$C$27
Name currentYear_working_capital_net: Ratios!$C$27
Name debt_long_term_equity: Ratios!$C$36
Name INC_cost_goods_sold: 'Income Statement'!$C$5
Name INC_depreciation: 'Income Statement'!$C$7
Name INC_ebit: 'Income Statement'!$C$8
Name INC_interest_expense: 'Income Statement'!$C$11
Name INC_net: 'Income Statement'!$C$15
Name INC_sales: 'Income Statement'!$C$4
Name market_capitalization: Ratios!$C$9
Name RATIO_asset_turnover: Ratios!$C$53
Name RATIO_debt_burden: Ratios!$C$67
Name RATIO_leverage: Ratios!$C$68
Name RATIO_operating_profit_margin: Ratios!$C$59
Name share_price: Ratios!$C$5
Name shares_outstanding: Ratios!$C$6
Name startYear_equity: Ratios!$C$12
Name startYear_inventory: Ratios!$C$13
Name startYear_receivables: Ratios!$C$14
Name startYear_total_assets: Ratios!$C$15
Name startYear_total_capitalization: Ratios!$C$16
Name tax_rate: Ratios!$C$8
Name yearCurrent: Ratios!$C$3

Sheet Balance Sheet
B1: Balance Sheet — Apple Inc. (AAPL)
B2: ASSETS | C2: FY2024 (Sep 28, 2024 | D2: FY2023 (Sep 30,2023) | F2: LIABILITIES & EQUITY | G2: FY2024 (Sep 28, 2024) | H2: FY2023 (Sep 30, 2023)
B3: (All figures in $millions) | F3: (All figures in $millions)
B4: Current Assets | F4: Current Liabilities
B5: Cash and marketable securities | C5: 65171 | D5: 61555 | F5: Debt due for repayment | G5: 10912 | H5: 9822
B6: Receivables | C6: 33410 | D6: 29508 | F6: Accounts payable | G6: 68960 | H6: 62611
B7: Inventories | C7: 7286 | D7: 6331 | F7: Other current liabilities | G7: 96520 | H7: 72875
B8: Other current assets | C8: 47120 | D8: 46172 | F8: Total current liabilities | G8: =SUM(G5:G7) -> 176392 | H8: =SUM(H5:H7) -> 145308
B9: Total current assets | C9: =SUM(C5:C8) -> 152987 | D9: =SUM(D5:D8) -> 143566
F10: Long-term debt | G10: 85750 | H10: 95281
B11: Fixed Assets | F11: Other long-term liabilities | G11: 45888 | H11: 49848
B12: Property, plant, and equipment | C12: 119128 | D12: 109528
B13: Less accumulated depreciation | C13: 73448 | D13: 65813 | F13: Total Liabilities | G13: =G8+G10+G11 -> 308030 | H13: =H8+H10+H11 -> 290437
B14: Net tangible fixed assets | C14: =C12-C13 -> 45680 | D14: =D12-D13 -> 43715
F15: Shareholders' Equity
B16: Other Assets | F16: Common stock and paid-in capital | G16: 83276 | H16: 73812
B17: Retained earnings/Accum. other comp. loss | C17: 0 | D17: 0 | F17: Retained earnings | G17: -26326 | H17: -11666
B18: Other assets | C18: =G20-C9-C14-C17 -> 166313 | D18: =H20-D9-D14-D17 -> 165302 | F18: Total shareholders' equity | G18: =SUM(G16:G17) -> 56950 | H18: =SUM(H16:H17) -> 62146
C20: =C9+C14+C18 -> 364980 | D20: =D9+D14+D18 -> 352583 | G20: =G13+G18 -> 364980 | H20: =H13+H18 -> 352583
B21: Balance Check (TA-TL&E) | C21: =C20-G20 -> 0
B22: Source: Apple 10-K FY2024, SEC EDGAR

Sheet Income Statement
B1: Income Statement — Apple Inc. (AAPL)
B2: Line Item | C2: FY2024 (Sep 28, 2024) | D2: % of Sales
B3: (All figures in $millions)
B4: Net sales | C4: 391035 | D4: =C4/C4 -> 1
B5: less Cost of goods sold | C5: 210352 | D5: =C5/C4 -> 0.5379365
B6: less Selling, general & administrative | C6: 26097 | D6: =C6/C4 -> 0.066738272
B7: less Depreciation | C7: 11445 | D7: =C7/C4 -> 0.02926848
B8: Earnings before interest & taxes (EBIT) | C8: =C4-SUM(C5:C7) -> 143141 | D8: =C8/C4 -> 0.36605675
B10: plus Other income | C10: 3764 | D10: =C10/C4 -> 0.0096257368
B11: less Interest expense | C11: 3931 | D11: =C11/C4 -> 0.010052809
B12: Taxable income | C12: =C8+C10-C11 -> 142974 | D12: =C12/C4 -> 0.36562968
B14: less Taxes | C14: 29749 | D14: =C14/C4 -> 0.076077589
B15: Net income | C15: =C12-C14 -> 113225 | D15: =C15/C4 -> 0.28955209
B17: Allocation of Net Income | C17: =C15 -> 113225 | D17: =D15 -> 0.28955209
B18: Dividends | C18: 15234 | D18: =C18/C4 -> 0.03895815
B19: Addition to retained earnings | C19: =C15-C18 -> 97991 | D19: =C19/C4 -> 0.25059394
B21: Source: Apple 10-K FY2024, SEC EDGAR

Sheet Cash Flow Statement
B1: Cash Flow Statement — Apple Inc. (AAPL)
B2: Line Item | C2: FY2024 (Sep 28, 2024) | D2: Source/Notes
B3: (All figures in $millions)
B4: Operations:
B5: Net income | C5: ='Income Statement'!C15 -> 113225 | D5: [Income Statement]
B6: plus Depreciation | C6: ='Income Statement'!C7 -> 11445 | D6: [Income Statement]
B7: plus Changes in working capital items
B8: Decrease (increase) in accounts receivable | C8: ='Balance Sheet'!D6-'Balance Sheet'!C6 -> -3902 | D8: [Balance Sheet]
B9: Decrease (increase) in inventories | C9: ='Balance Sheet'!D7-'Balance Sheet'!C7 -> -955 | D9: [Balance Sheet]
B10: Decrease (increase) in other current assets | C10: ='Balance Sheet'!D8-'Balance Sheet'!C8 -> -948 | D10: [Balance Sheet]
B11: Increase (decrease) in accounts payable | C11: ='Balance Sheet'!G6-'Balance Sheet'!H6 -> 6349 | D11: [Balance Sheet]
B12: Increase (decrease) in other current liabilities | C12: ='Balance Sheet'!G7-'Balance Sheet'!H7 -> 23645 | D12: [Balance Sheet]
B13: Total change in working capital | C13: =SUM(C8:C12) -> 24189
B14: Cash provided by operations | C14: =C5+C6+C13 -> 148859
B16: Investments:
B17: Capital expenditures | C17: -9447
B18: plus Sales (acquisitions) of long-term assets | C18: 13690
B19: plus Other investing activities | C19: -1308
B20: Cash provided by (used for) investments | C20: =SUM(C17:C19) -> 2935
B22: Financing activities:
B23: Increase (decrease) in short-term debt | C23: -9958
B24: plus Increase (decrease) in long-term debt | C24: 3960
B25: plus Dividends | C25: -15234
B26: plus Issues (repurchases) of stock | C26: -94949
B27: plus Other | C27: -5802
B28: Cash provided by (used for) financing | C28: =SUM(C23:C27) -> -121983
B30: Net increase (decrease) in cash | C30: =C14+C20+C28 -> 29811
B32: Source: Apple 10-K FY2024, SEC EDGAR

Sheet Ratios
B1: Ratios — Apple Inc. (AAPL)
B2: Metric | C2: Input | D2: Named Range Formula | E2: Named Range
B3: Current year | C3: 2024 | E3: yearCurrent
B4: Start of year | C4: =C3-1 -> 2023 | D4: yearCurrent-1 | E4: yearStart
B5: Share price | C5: 226.51 | E5: share_price
B6: Shares outstanding (M) | C6: 15204 | E6: shares_outstanding
B7: Cost of capital | C7: 0.09 | E7: cost_capital
B8: Tax rate | C8: 0.241 | E8: tax_rate
B9: Market capitalization | C9: =share_price*shares_outstanding -> 3443858 | D9: share_price x shares_outstanding | E9: market_capitalization
B11: — Start of Year (Prior Year Balance Sheet) —
B12: Equity (start of year) | C12: =BAL_equity_shareholders_2023 -> 62146 | D12: BAL_equity_shareholders_2023 | E12: startYear_equity
B13: Inventories (start of year) | C13: =BAL_inventories_2023 -> 6331 | D13: BAL_inventories_2023 | E13: startYear_inventory
B14: Receivables (start of year) | C14: =BAL_receivables_2023 -> 29508 | D14: BAL_receivables_2023 | E14: startYear_receivables
B15: Total assets (start of year) | C15: =BAL_assets_total_2023 -> 352583 | D15: BAL_assets_total_2023 | E15: startYear_total_assets
B16: Total capitalization (start of year) | C16: =BAL_debt_long_term_2023+BAL_equity_shareholders_2023 -> 157427 | D16: BAL_debt_long_term_2023+BAL_equity_shareholders_2023 | E16: startYear_total_capitalization
B18: — Current Year (Derived) —
B19: After-tax operating income | C19: {=INC_net+(1-tax_rate)*INC_interest_expense} -> 116208.63 | D19: INC_net + (1-tax_rate) x INC_interest_expense | E19: currentYear_after_tax_operating_income
B20: Average daily sales | C20: =INC_sales/365 -> 1071.3288 | D20: INC_sales / 365 | E20: currentYear_daily_sales_average
B21: Book value of equity | C21: =BAL_equity_shareholders_2024 -> 56950 | D21: BAL_equity_shareholders_2024 | E21: currentYear_equity
B22: Cash + Mktable securities | C22: =BAL_cash_marketable_securities_2024 -> 65171 | D22: BAL_cash_marketable_securities_2024 | E22: currentYear_cash_marketable_securities
B23: Current assets | C23: =BAL_assets_current_2024 -> 152987 | D23: BAL_assets_current_2024 | E23: currentYear_assets_current
B24: Current liabilities | C24: =BAL_liabilities_current_2024 -> 176392 | D24: BAL_liabilities_current_2024 | E24: currentYear_liabilities_current
B25: Daily COGS | C25: =INC_cost_goods_sold/365 -> 576.30685 | D25: INC_cost_goods_sold / 365 | E25: currentYear_cost_goods_sold_daily
B26: Long-term debt | C26: =BAL_debt_long_term_2024 -> 85750 | D26: BAL_debt_long_term_2024 | E26: currentYear_debt_long_term
B27: Net working capital | C27: =BAL_assets_current_2024-BAL_liabilities_current_2024 -> -23405 | D27: BAL_assets_current_2024 - BAL_liabilities_current_2024 | E27: currentYear_working_capital_net
B28: Total assets | C28: =BAL_assets_total_2024 -> 364980 | D28: BAL_assets_total_2024 | E28: currentYear_assets_total
B29: Total capitalization | C29: =BAL_debt_long_term_2024+BAL_equity_shareholders_2024 -> 142700 | D29: BAL_debt_long_term_2024 + BAL_equity_shareholders_2024 | E29: currentYear_total_capitalization
B30: Total liabilities | C30: =BAL_liabilities_total_2024 -> 308030 | D30: BAL_liabilities_total_2024 | E30: currentYear_liabilities_total
B32: — Mixed Year (Averages) —
B33: Average equity | C33: =AVERAGE(startYear_equity,currentYear_equity) -> 59548 | D33: AVERAGE(startYear_equity, currentYear_equity) | E33: avg_equity
B34: Average total assets | C34: =AVERAGE(startYear_total_assets,currentYear_assets_total) -> 358781.5 | D34: AVERAGE(startYear_total_assets, currentYear_assets_total) | E34: avg_total_assets
B35: Average total capitalization | C35: =AVERAGE(startYear_total_capitalization,currentYear_total_capitalization) -> 150063.5 | D35: AVERAGE(startYear_total_capitalization, currentYear_total_capitalization) | E35: avg_total_capitalization
B36: Long-term debt + Equity | C36: =currentYear_debt_long_term+currentYear_equity -> 142700 | D36: currentYear_debt_long_term + currentYear_equity | E36: debt_long_term_equity
B38: Ratio | C38: Output | D38: Named Range Formula (reference) | E38: Named Range
B39: Performance
B40: Market value added (MVA) | C40: =market_capitalization-currentYear_equity -> 3386908 | D40: market_capitalization - currentYear_equity
B41: Market-to-book ratio | C41: =market_capitalization/currentYear_equity -> 60.471607 | D41: market_capitalization / currentYear_equity
B42: Economic value added (EVA) | C42: =currentYear_after_tax_operating_income-(cost_capital*startYear_total_capitalization) -> 102040.2 | D42: currentYear_after_tax_operating_income - (cost_capital x startYear_total_capitalization)
B44: Profitability
B45: Return on assets (ROA) | C45: =currentYear_after_tax_operating_income/startYear_total_assets -> 0.32959226 | D45: currentYear_after_tax_operating_income / startYear_total_assets
...

Sheet Notes
B1: Notes & Assumptions — Apple Inc. (AAPL)
B3: Company: | C3: Apple Inc.
B4: Ticker: | C4: AAPL
B5: Industry: | C5: Technology - Consumer Electronics & Software
B6: Fiscal Year (current): | C6: FY2024 (Sep 28, 2024)
B7: Fiscal Year (prior): | C7: FY2023 (Sep 30, 2023)
B8: Data Source: | C8: Apple 10-K FY2024, SEC EDGAR
B9: Units: | C9: All figures in millions of US dollars otherwise noted.
B10: Tax Rate: | C10: 24.1% - use as analyst assumption (adjust to effective rate if preferred)
B11: Cost of Capital: | C11: 9.0% - estimated WACC; students may refine using CAPM + class methodology
B12: Share Price: | C12: $226.51 - end-of-fiscal-year closing price
B13: Shares Outstanding: | C13: 15,24M shares
B15: BUS-314 Project Use: | C15: This workbook provides real financial statement data for the Accounting & Performance Ratios project.
... B20: AI Usage: | C20: Claude was used to generate and refine the memo from stage 1, as well as to pull the data from the "Apple 10-K FY2024, SEC EDGAR" and populate the template for this spreadsheet.
